import {renderHook, act} from '@testing-library/react-hooks'
import {useAsync} from '../hooks'


function deferred() {
  let resolve, reject
  const promise = new Promise((res, rej) => {
    resolve = res
    reject = rej
  })
  return {promise, resolve, reject}
}

test('calling run with a promise which resolves', async () => {
  let resolve, reject
  const promise = new Promise((res, rej) => {
    resolve = res
    reject = rej
  })

  const {result} = renderHook(() => useAsync())
  expect(result.current).toEqual({
    status: 'idle',
    data: null,
    error: null,

    isIdle: true,
    isLoading: false,
    isError: false,
    isSuccess: false,

    run: expect.any(Function),
    reset: expect.any(Function),
    setData: expect.any(Function),
    setError: expect.any(Function),
  })

  act(() => {
    result.current.run(promise)
  })
  
  expect(result.current).toEqual({
    status: 'pending',
    data: null,
    error: null,

    isIdle: false,
    isLoading: true,
    isError: false,
    isSuccess: false,

    run: expect.any(Function),
    reset: expect.any(Function),
    setData: expect.any(Function),
    setError: expect.any(Function),
  })
})

test('calling run with a promise which rejects', async () => {
    
})
// 🐨 this will be very similar to the previous test, except you'll reject the
// promise instead and assert on the error state.
// 💰 to avoid the promise actually failing your test, you can catch
//    the promise returned from `run` with `.catch(() => {})`

test('can specify an initial state', async () => {
    
})
// 💰 useAsync(customInitialState)

test('can set the data', async () => {
    
})
// 💰 result.current.setData('whatever you want')

test('can set the error', async () => {
    
})
// 💰 result.current.setError('whatever you want')

test('No state updates happen if the component is unmounted while pending', async () => {
    
})
// 💰 const {result, unmount} = renderHook(...)
// 🐨 ensure that console.error is not called (React will call console.error if updates happen when unmounted)

test('calling "run" without a promise results in an early error', async () => {
    
})
